Workbook

Sheet Leyenda
A1: Base de Datos de Seguimiento al Egresado y Graduado – EPMH-UAC
A2: Procedimiento PSC-S-06 Versión 03 (Res. N.° 072-CU-2025-UAC) · Matriz consolidada al 01/10/2026
A4: Cómo usar
A5: 1. Hoja Config: semestre, fecha de corte, responsable, metas y vigencia de la actualización. Las metas de 10.1 vienen del Anexo 01; las de 10.2, 10.4 y 10.5 son propuestas a aprobar.
A6: 2. Hoja Egresados: una fila por egresado de la relación oficial de Servicios Académicos (2017-2 a 2025-2). Llene solo las celdas amarillas; las celestes se calculan solas.
A7: 3. 'Datos actualizados' se calcula: Sí cuando la última actualización tiene menos días que la vigencia definida en Config (365 días por defecto).
A8: 4. Hoja Empleadores: una fila por institución. El ID (EMP-###) se usa en la columna 'ID empleador' de Egresados.
A9: 5. Hoja Actividades: una fila por actividad, con su evidencia (numeral 7.18). Marque 'Programada en el Plan' según el Plan de Trabajo aprobado.
A10: 6. Hoja Indicadores: se calcula sola. De aquí se copian las cifras a los informes mensual y final.
A11: 7. Hoja Por conciliar: egresados que respondieron encuestas pero no figuran en la relación oficial (egresaron antes de 2017-2 o en 2026). Verifique su código y agréguelos a Egresados.
A12: 8. El dashboard del Director lee este archivo: no cambie nombres de hojas ni encabezados de columna.
A14: Convención de colores
... A27: Satisfacción con el perfil (1–5) = pregunta 'Satisfacción con la calidad de formación' de la Encuesta primera de egreso: Totalmente de acuerdo 5, De acuerdo 4, Neutral 3, Desacuerdo 2.

Sheet Config
B1: Configuración
B2: Escuela Profesional | C2: Medicina Humana
B3: Semestre en curso | C3: 2026-II
B4: Fecha de corte | C4: 46296
B5: Docente responsable | C5: [Nombre]
B6: Resolución del Plan de Trabajo | C6: [N.° ___-CF-2026]
B8: Meta 10.1 – Tramo 1 | C8: 0.9 | D8: Fuente: Anexo 01 del PSC-S-06
B9: Meta 10.1 – Tramo 2 | C9: 0.8
B10: Meta 10.1 – Tramo 3 | C10: 0.7
B11: Meta 10.1 – Tramo 4 | C11: 0.6
B12: Meta 10.2 – En su especialidad | C12: 0.7 | D12: Propuesta – aprobar por la Dirección
B13: Meta 10.4 – Satisfacción perfil de egreso | C13: 0.8 | D13: Propuesta – aprobar por la Dirección
B14: Meta 10.5 – Empleabilidad | C14: 0.85 | D14: Propuesta – aprobar por la Dirección
B15: Vigencia de la actualización (días) | C15: 365 | D15: Supuesto: datos confirmados en los últimos 12 meses; ajústelo si la Dirección define otro plazo

Sheet Indicadores
A1: Indicadores del PSC-S-06 – EPMH
A2: ="Fecha de corte: "&TEXT(Config!C4,"dd/mm/yyyy")&" · Semestre "&Config!C3&" · Vigencia de actualización: "&Config!C15&" días" -> Fecha de corte: 01/10/2026 · Semestre 2026-II · Vigencia de actualización: 365 días
A4: 10.1 Porcentaje de egresados registrados por tramo
A5: Tramo | B5: Universo (egresados en BD) | C5: Registrados (datos actualizados) | D5: % logrado | E5: Meta | F5: Brecha (pp) | G5: Semáforo
A6: Tramo 1 | B6: =COUNTIF(Egresados!$I$2:$I$1501,A6) -> 147 | C6: =COUNTIFS(Egresados!$I$2:$I$1501,A6,Egresados!$U$2:$U$1501,"Sí") -> 0 | D6: =IF(B6=0,0,C6/B6) -> 0 | E6: =Config!C8 -> 0.9 | F6: =(D6-E6)*100 -> -90 | G6: =IF(B6=0,"Sin datos",IF(D6>=E6,"Cumple",IF(D6>=E6-0.1,"En proceso","Crítico"))) -> Crítico
A7: Tramo 2 | B7: =COUNTIF(Egresados!$I$2:$I$1501,A7) -> 459 | C7: =COUNTIFS(Egresados!$I$2:$I$1501,A7,Egresados!$U$2:$U$1501,"Sí") -> 80 | D7: =IF(B7=0,0,C7/B7) -> 0.17429194 | E7: =Config!C9 -> 0.8 | F7: =(D7-E7)*100 -> -62.570806 | G7: =IF(B7=0,"Sin datos",IF(D7>=E7,"Cumple",IF(D7>=E7-0.1,"En proceso","Crítico"))) -> Crítico
A8: Tramo 3 | B8: =COUNTIF(Egresados!$I$2:$I$1501,A8) -> 206 | C8: =COUNTIFS(Egresados!$I$2:$I$1501,A8,Egresados!$U$2:$U$1501,"Sí") -> 15 | D8: =IF(B8=0,0,C8/B8) -> 0.072815534 | E8: =Config!C10 -> 0.7 | F8: =(D8-E8)*100 -> -62.718447 | G8: =IF(B8=0,"Sin datos",IF(D8>=E8,"Cumple",IF(D8>=E8-0.1,"En proceso","Crítico"))) -> Crítico
A9: Tramo 4 | B9: =COUNTIF(Egresados!$I$2:$I$1501,A9) -> 164 | C9: =COUNTIFS(Egresados!$I$2:$I$1501,A9,Egresados!$U$2:$U$1501,"Sí") -> 19 | D9: =IF(B9=0,0,C9/B9) -> 0.11585366 | E9: =Config!C11 -> 0.6 | F9: =(D9-E9)*100 -> -48.414634 | G9: =IF(B9=0,"Sin datos",IF(D9>=E9,"Cumple",IF(D9>=E9-0.1,"En proceso","Crítico"))) -> Crítico
A10: Total | B10: =SUM(B6:B9) -> 976 | C10: =SUM(C6:C9) -> 114 | D10: =IF(B10=0,0,C10/B10) -> 0.11680328
A12: 10.2 / 10.5 Situación laboral y especialidad (sobre egresados con situación laboral conocida)
A13: Tramo | B13: Con situación conocida | C13: Con empleo | D13: En su especialidad | E13: 10.5 Empleabilidad | F13: 10.2 En su especialidad | G13: Sin información
A14: Tramo 1 | B14: =C14+COUNTIFS(Egresados!$I$2:$I$1501,A14,Egresados!$P$2:$P$1501,"No") -> 0 | C14: =COUNTIFS(Egresados!$I$2:$I$1501,A14,Egresados!$P$2:$P$1501,"Sí") -> 0 | D14: =COUNTIFS(Egresados!$I$2:$I$1501,A14,Egresados!$Q$2:$Q$1501,"Sí") -> 0 | E14: =IF(B14=0,0,C14/B14) -> 0 | F14: =IF(B14=0,0,D14/B14) -> 0 | G14: =COUNTIFS(Egresados!$I$2:$I$1501,A14,Egresados!$O$2:$O$1501,"Sin información") -> 147
A15: Tramo 2 | B15: =C15+COUNTIFS(Egresados!$I$2:$I$1501,A15,Egresados!$P$2:$P$1501,"No") -> 69 | C15: =COUNTIFS(Egresados!$I$2:$I$1501,A15,Egresados!$P$2:$P$1501,"Sí") -> 19 | D15: =COUNTIFS(Egresados!$I$2:$I$1501,A15,Egresados!$Q$2:$Q$1501,"Sí") -> 18 | E15: =IF(B15=0,0,C15/B15) -> 0.27536232 | F15: =IF(B15=0,0,D15/B15) -> 0.26086957 | G15: =COUNTIFS(Egresados!$I$2:$I$1501,A15,Egresados!$O$2:$O$1501,"Sin información") -> 390
A16: Tramo 3 | B16: =C16+COUNTIFS(Egresados!$I$2:$I$1501,A16,Egresados!$P$2:$P$1501,"No") -> 38 | C16: =COUNTIFS(Egresados!$I$2:$I$1501,A16,Egresados!$P$2:$P$1501,"Sí") -> 28 | D16: =COUNTIFS(Egresados!$I$2:$I$1501,A16,Egresados!$Q$2:$Q$1501,"Sí") -> 28 | E16: =IF(B16=0,0,C16/B16) -> 0.73684211 | F16: =IF(B16=0,0,D16/B16) -> 0.73684211 | G16: =COUNTIFS(Egresados!$I$2:$I$1501,A16,Egresados!$O$2:$O$1501,"Sin información") -> 168
A17: Tramo 4 | B17: =C17+COUNTIFS(Egresados!$I$2:$I$1501,A17,Egresados!$P$2:$P$1501,"No") -> 17 | C17: =COUNTIFS(Egresados!$I$2:$I$1501,A17,Egresados!$P$2:$P$1501,"Sí") -> 17 | D17: =COUNTIFS(Egresados!$I$2:$I$1501,A17,Egresados!$Q$2:$Q$1501,"Sí") -> 17 | E17: =IF(B17=0,0,C17/B17) -> 1 | F17: =IF(B17=0,0,D17/B17) -> 1 | G17: =COUNTIFS(Egresados!$I$2:$I$1501,A17,Egresados!$O$2:$O$1501,"Sin información") -> 147
A18: Total | B18: =SUM(B14:B17) -> 124 | C18: =SUM(C14:C17) -> 64 | D18: =SUM(D14:D17) -> 63 | E18: =IF(B18=0,0,C18/B18) -> 0.51612903 | F18: =IF(B18=0,0,D18/B18) -> 0.50806452 | G18: =SUM(G14:G17) -> 852
A21: Resumen de indicadores
A22: Código | B22: Indicador | C22: Resultado | D22: Meta | E22: Brecha (pp) | F22: Semáforo | G22: Base (n)
A23: 10.1 | B23: Egresados registrados (total) | C23: =D10 -> 0.11680328 | G23: =B10 -> 976
A24: 10.2 | B24: Laborando en su especialidad | C24: =F18 -> 0.50806452 | D24: =Config!C12 -> 0.7 | E24: =IF(D24="","",(C24-D24)*100) -> -19.193548 | F24: =IF(D24="","",IF(C24>=D24,"Cumple",IF(C24>=D24-0.1,"En proceso","Crítico"))) -> Crítico | G24: =B18 -> 124
A25: 10.4 | B25: Satisfacción con el perfil de egreso (4–5) | C25: =IF(COUNT(Egresados!$X$2:$X$1501)=0,0,COUNTIF(Egresados!$X$2:$X$1501,">=4")/COUNT(Egresados!$X$2:$X$1501)) -> 0.46153846 | D25: =Config!C13 -> 0.8 | E25: =IF(D25="","",(C25-D25)*100) -> -33.846154 | F25: =IF(D25="","",IF(C25>=D25,"Cumple",IF(C25>=D25-0.1,"En proceso","Crítico"))) -> Crítico | G25: =COUNT(Egresados!$X$2:$X$1501) -> 13
A26: 10.5 | B26: Empleabilidad alcanzada | C26: =E18 -> 0.51612903 | D26: =Config!C14 -> 0.85 | E26: =IF(D26="","",(C26-D26)*100) -> -33.387097 | F26: =IF(D26="","",IF(C26>=D26,"Cumple",IF(C26>=D26-0.1,"En proceso","Crítico"))) -> Crítico | G26: =B18 -> 124
A27: 8.4 | B27: Satisfacción de empleadores (4–5) | C27: =IF(COUNT(Empleadores!$N$2:$N$601)=0,0,COUNTIF(Empleadores!$N$2:$N$601,">=4")/COUNT(Empleadores!$N$2:$N$601)) -> 0 | G27: =COUNT(Empleadores!$N$2:$N$601) -> 0
A28: Plan | B28: Ejecución de actividades programadas | C28: =IF(COUNTIF(Actividades!$H$2:$H$300,"Sí")=0,0,COUNTIFS(Actividades!$H$2:$H$300,"Sí",Actividades!$I$2:$I$300,"Ejecutada")/COUNTIF(Actividades!$H$2:$H$300,"Sí")) -> 0 | G28: =COUNTIF(Actividades!$H$2:$H$300,"Sí") -> 0
A29: SERUMS | B29: Egresados en la lista SERUMS 2026-II (MINSA) | C29: =COUNTIF(Egresados!$AA$2:$AA$1501,"Postulante SERUMS 2026-II*") -> 158
A31: 10.3 Situación laboral por semestre de egreso (% sobre egresados del semestre con situación conocida)
A32: Semestre de egreso | B32: Asistencial | C32: SERUMS | D32: Residentado | E32: Gestión o docencia en salud | F32: Otra área | G32: Posgrado sin laborar | H32: Sin empleo | I32: Con situación conocida | J32: Sin información
A33: 2017-I | B33: =IF($I33=0,"",COUNTIFS(Egresados!$F$2:$F$1501,$A33,Egresados!$O$2:$O$1501,"Asistencial")/$I33) | C33: =IF($I33=0,"",COUNTIFS(Egresados!$F$2:$F$1501,$A33,Egresados!$O$2:$O$1501,"SERUMS")/$I33) | D33: =IF($I33=0,"",COUNTIFS(Egresados!$F$2:$F$1501,$A33,Egresados!$O$2:$O$1501,"Residentado")/$I33) | E33: =IF($I33=0,"",COUNTIFS(Egresados!$F$2:$F$1501,$A33,Egresados!$O$2:$O$1501,"Gestión o docencia en salud")/$I33) | F33: =IF($I33=0,"",COUNTIFS(Egresados!$F$2:$F$1501,$A33,Egresados!$O$2:$O$1501,"Otra área")/$I33) | G33: =IF($I33=0,"",COUNTIFS(Egresados!$F$2:$F$1501,$A33,Egresados!$O$2:$O$1501,"Posgrado sin laborar")/$I33) | H33: =IF($I33=0,"",COUNTIFS(Egresados!$F$2:$F$1501,$A33,Egresados!$O$2:$O$1501,"Sin empleo")/$I33) | I33: =COUNTIFS(Egresados!$F$2:$F$1501,$A33,Egresados!$O$2:$O$1501,"<>Sin información",Egresados!$O$2:$O$1501,"<>") -> 0 | J33: =COUNTIFS(Egresados!$F$2:$F$1501,$A33,Egresados!$O$2:$O$1501,"Sin información") -> 0
A34: 2017-II | B34: =IF($I34=0,"",COUNTIFS(Egresados!$F$2:$F$1501,$A34,Egresados!$O$2:$O$1501,"Asistencial")/$I34) -> 1 | C34: =IF($I34=0,"",COUNTIFS(Egresados!$F$2:$F$1501,$A34,Egresados!$O$2:$O$1501,"SERUMS")/$I34) -> 0 | D34: =IF($I34=0,"",COUNTIFS(Egresados!$F$2:$F$1501,$A34,Egresados!$O$2:$O$1501,"Residentado")/$I34) -> 0 | E34: =IF($I34=0,"",COUNTIFS(Egresados!$F$2:$F$1501,$A34,Egresados!$O$2:$O$1501,"Gestión o docencia en salud")/$I34) -> 0 | F34: =IF($I34=0,"",COUNTIFS(Egresados!$F$2:$F$1501,$A34,Egresados!$O$2:$O$1501,"Otra área")/$I34) -> 0 | G34: =IF($I34=0,"",COUNTIFS(Egresados!$F$2:$F$1501,$A34,Egresados!$O$2:$O$1501,"Posgrado sin laborar")/$I34) -> 0 | H34: =IF($I34=0,"",COUNTIFS(Egresados!$F$2:$F$1501,$A34,Egresados!$O$2:$O$1501,"Sin empleo")/$I34) -> 0 | I34: =COUNTIFS(Egresados!$F$2:$F$1501,$A34,Egresados!$O$2:$O$1501,"<>Sin información",Egresados!$O$2:$O$1501,"<>") -> 7 | J34: =COUNTIFS(Egresados!$F$2:$F$1501,$A34,Egresados!$O$2:$O$1501,"Sin información") -> 39
A35: 2018-I | B35: =IF($I35=0,"",COUNTIFS(Egresados!$F$2:$F$1501,$A35,Egresados!$O$2:$O$1501,"Asistencial")/$I35) | C35: =IF($I35=0,"",COUNTIFS(Egresados!$F$2:$F$1501,$A35,Egresados!$O$2:$O$1501,"SERUMS")/$I35) | D35: =IF($I35=0,"",COUNTIFS(Egresados!$F$2:$F$1501,$A35,Egresados!$O$2:$O$1501,"Residentado")/$I35) | E35: =IF($I35=0,"",COUNTIFS(Egresados!$F$2:$F$1501,$A35,Egresados!$O$2:$O$1501,"Gestión o docencia en salud")/$I35) | F35: =IF($I35=0,"",COUNTIFS(Egresados!$F$2:$F$1501,$A35,Egresados!$O$2:$O$1501,"Otra área")/$I35) | G35: =IF($I35=0,"",COUNTIFS(Egresados!$F$2:$F$1501,$A35,Egresados!$O$2:$O$1501,"Posgrado sin laborar")/$I35) | H35: =IF($I35=0,"",COUNTIFS(Egresados!$F$2:$F$1501,$A35,Egresados!$O$2:$O$1501,"Sin empleo")/$I35) | I35: =COUNTIFS(Egresados!$F$2:$F$1501,$A35,Egresados!$O$2:$O$1501,"<>Sin información",Egresados!$O$2:$O$1501,"<>") -> 0 | J35: =COUNTIFS(Egresados!$F$2:$F$1501,$A35,Egresados!$O$2:$O$1501,"Sin información") -> 0
A36: 2018-II | B36: =IF($I36=0,"",COUNTIFS(Egresados!$F$2:$F$1501,$A36,Egresados!$O$2:$O$1501,"Asistencial")/$I36) -> 1 | C36: =IF($I36=0,"",COUNTIFS(Egresados!$F$2:$F$1501,$A36,Egresados!$O$2:$O$1501,"SERUMS")/$I36) -> 0 | D36: =IF($I36=0,"",COUNTIFS(Egresados!$F$2:$F$1501,$A36,Egresados!$O$2:$O$1501,"Residentado")/$I36) -> 0 | E36: =IF($I36=0,"",COUNTIFS(Egresados!$F$2:$F$1501,$A36,Egresados!$O$2:$O$1501,"Gestión o docencia en salud")/$I36) -> 0 | F36: =IF($I36=0,"",COUNTIFS(Egresados!$F$2:$F$1501,$A36,Egresados!$O$2:$O$1501,"Otra área")/$I36) -> 0 | G36: =IF($I36=0,"",COUNTIFS(Egresados!$F$2:$F$1501,$A36,Egresados!$O$2:$O$1501,"Posgrado sin laborar")/$I36) -> 0 | H36: =IF($I36=0,"",COUNTIFS(Egresados!$F$2:$F$1501,$A36,Egresados!$O$2:$O$1501,"Sin empleo")/$I36) -> 0 | I36: =COUNTIFS(Egresados!$F$2:$F$1501,$A36,Egresados!$O$2:$O$1501,"<>Sin información",Egresados!$O$2:$O$1501,"<>") -> 3 | J36: =COUNTIFS(Egresados!$F$2:$F$1501,$A36,Egresados!$O$2:$O$1501,"Sin información") -> 30
A37: 2019-I | B37: =IF($I37=0,"",COUNTIFS(Egresados!$F$2:$F$1501,$A37,Egresados!$O$2:$O$1501,"Asistencial")/$I37) | C37: =IF($I37=0,"",COUNTIFS(Egresados!$F$2:$F$1501,$A37,Egresados!$O$2:$O$1501,"SERUMS")/$I37) | D37: =IF($I37=0,"",COUNTIFS(Egresados!$F$2:$F$1501,$A37,Egresados!$O$2:$O$1501,"Residentado")/$I37) | E37: =IF($I37=0,"",COUNTIFS(Egresados!$F$2:$F$1501,$A37,Egresados!$O$2:$O$1501,"Gestión o docencia en salud")/$I37) | F37: =IF($I37=0,"",COUNTIFS(Egresados!$F$2:$F$1501,$A37,Egresados!$O$2:$O$1501,"Otra área")/$I37) | G37: =IF($I37=0,"",COUNTIFS(Egresados!$F$2:$F$1501,$A37,Egresados!$O$2:$O$1501,"Posgrado sin laborar")/$I37) | H37: =IF($I37=0,"",COUNTIFS(Egresados!$F$2:$F$1501,$A37,Egresados!$O$2:$O$1501,"Sin empleo")/$I37) | I37: =COUNTIFS(Egresados!$F$2:$F$1501,$A37,Egresados!$O$2:$O$1501,"<>Sin información",Egresados!$O$2:$O$1501,"<>") -> 0 | J37: =COUNTIFS(Egresados!$F$2:$F$1501,$A37,Egresados!$O$2:$O$1501,"Sin información") -> 1
A38: 2019-II | B38: =IF($I38=0,"",COUNTIFS(Egresados!$F$2:$F$1501,$A38,Egresados!$O$2:$O$1501,"Asistencial")/$I38) -> 0.8 | C38: =IF($I38=0,"",COUNTIFS(Egresados!$F$2:$F$1501,$A38,Egresados!$O$2:$O$1501,"SERUMS")/$I38) -> 0 | D38: =IF($I38=0,"",COUNTIFS(Egresados!$F$2:$F$1501,$A38,Egresados!$O$2:$O$1501,"Residentado")/$I38) -> 0 | E38: =IF($I38=0,"",COUNTIFS(Egresados!$F$2:$F$1501,$A38,Egresados!$O$2:$O$1501,"Gestión o docencia en salud")/$I38) -> 0.2 | F38: =IF($I38=0,"",COUNTIFS(Egresados!$F$2:$F$1501,$A38,Egresados!$O$2:$O$1501,"Otra área")/$I38) -> 0 | G38: =IF($I38=0,"",COUNTIFS(Egresados!$F$2:$F$1501,$A38,Egresados!$O$2:$O$1501,"Posgrado sin laborar")/$I38) -> 0 | H38: =IF($I38=0,"",COUNTIFS(Egresados!$F$2:$F$1501,$A38,Egresados!$O$2:$O$1501,"Sin empleo")/$I38) -> 0 | I38: =COUNTIFS(Egresados!$F$2:$F$1501,$A38,Egresados!$O$2:$O$1501,"<>Sin información",Egresados!$O$2:$O$1501,"<>") -> 5 | J38: =COUNTIFS(Egresados!$F$2:$F$1501,$A38,Egresados!$O$2:$O$1501,"Sin información") -> 38
A39: 2020-I | B39: =IF($I39=0,"",COUNTIFS(Egresados!$F$2:$F$1501,$A39,Egresados!$O$2:$O$1501,"Asistencial")/$I39) | C39: =IF($I39=0,"",COUNTIFS(Egresados!$F$2:$F$1501,$A39,Egresados!$O$2:$O$1501,"SERUMS")/$I39) | D39: =IF($I39=0,"",COUNTIFS(Egresados!$F$2:$F$1501,$A39,Egresados!$O$2:$O$1501,"Residentado")/$I39) | E39: =IF($I39=0,"",COUNTIFS(Egresados!$F$2:$F$1501,$A39,Egresados!$O$2:$O$1501,"Gestión o docencia en salud")/$I39) | F39: =IF($I39=0,"",COUNTIFS(Egresados!$F$2:$F$1501,$A39,Egresados!$O$2:$O$1501,"Otra área")/$I39) | G39: =IF($I39=0,"",COUNTIFS(Egresados!$F$2:$F$1501,$A39,Egresados!$O$2:$O$1501,"Posgrado sin laborar")/$I39) | H39: =IF($I39=0,"",COUNTIFS(Egresados!$F$2:$F$1501,$A39,Egresados!$O$2:$O$1501,"Sin empleo")/$I39) | I39: =COUNTIFS(Egresados!$F$2:$F$1501,$A39,Egresados!$O$2:$O$1501,"<>Sin información",Egresados!$O$2:$O$1501,"<>") -> 0 | J39: =COUNTIFS(Egresados!$F$2:$F$1501,$A39,Egresados!$O$2:$O$1501,"Sin información") -> 0
A40: 2020-II | B40: =IF($I40=0,"",COUNTIFS(Egresados!$F$2:$F$1501,$A40,Egresados!$O$2:$O$1501,"Asistencial")/$I40) | C40: =IF($I40=0,"",COUNTIFS(Egresados!$F$2:$F$1501,$A40,Egresados!$O$2:$O$1501,"SERUMS")/$I40) | D40: =IF($I40=0,"",COUNTIFS(Egresados!$F$2:$F$1501,$A40,Egresados!$O$2:$O$1501,"Residentado")/$I40) | E40: =IF($I40=0,"",COUNTIFS(Egresados!$F$2:$F$1501,$A40,Egresados!$O$2:$O$1501,"Gestión o docencia en salud")/$I40) | F40: =IF($I40=0,"",COUNTIFS(Egresados!$F$2:$F$1501,$A40,Egresados!$O$2:$O$1501,"Otra área")/$I40) | G40: =IF($I40=0,"",COUNTIFS(Egresados!$F$2:$F$1501,$A40,Egresados!$O$2:$O$1501,"Posgrado sin laborar")/$I40) | H40: =IF($I40=0,"",COUNTIFS(Egresados!$F$2:$F$1501,$A40,Egresados!$O$2:$O$1501,"Sin empleo")/$I40) | I40: =COUNTIFS(Egresados!$F$2:$F$1501,$A40,Egresados!$O$2:$O$1501,"<>Sin información",Egresados!$O$2:$O$1501,"<>") -> 0 | J40: =COUNTIFS(Egresados!$F$2:$F$1501,$A40,Egresados!$O$2:$O$1501,"Sin información") -> 0
A41: 2021-I | B41: =IF($I41=0,"",COUNTIFS(Egresados!$F$2:$F$1501,$A41,Egresados!$O$2:$O$1501,"Asistencial")/$I41) -> 1 | C41: =IF($I41=0,"",COUNTIFS(Egresados!$F$2:$F$1501,$A41,Egresados!$O$2:$O$1501,"SERUMS")/$I41) -> 0 | D41: =IF($I41=0,"",COUNTIFS(Egresados!$F$2:$F$1501,$A41,Egresados!$O$2:$O$1501,"Residentado")/$I41) -> 0 | E41: =IF($I41=0,"",COUNTIFS(Egresados!$F$2:$F$1501,$A41,Egresados!$O$2:$O$1501,"Gestión o docencia en salud")/$I41) -> 0 | F41: =IF($I41=0,"",COUNTIFS(Egresados!$F$2:$F$1501,$A41,Egresados!$O$2:$O$1501,"Otra área")/$I41) -> 0 | G41: =IF($I41=0,"",COUNTIFS(Egresados!$F$2:$F$1501,$A41,Egresados!$O$2:$O$1501,"Posgrado sin laborar")/$I41) -> 0 | H41: =IF($I41=0,"",COUNTIFS(Egresados!$F$2:$F$1501,$A41,Egresados!$O$2:$O$1501,"Sin empleo")/$I41) -> 0 | I41: =COUNTIFS(Egresados!$F$2:$F$1501,$A41,Egresados!$O$2:$O$1501,"<>Sin información",Egresados!$O$2:$O$1501,"<>") -> 2 | J41: =COUNTIFS(Egresados!$F$2:$F$1501,$A41,Egresados!$O$2:$O$1501,"Sin información") -> 39
A42: 2021-II | B42: =IF($I42=0,"",COUNTIFS(Egresados!$F$2:$F$1501,$A42,Egresados!$O$2:$O$1501,"Asistencial")/$I42) | C42: =IF($I42=0,"",COUNTIFS(Egresados!$F$2:$F$1501,$A42,Egresados!$O$2:$O$1501,"SERUMS")/$I42) | D42: =IF($I42=0,"",COUNTIFS(Egresados!$F$2:$F$1501,$A42,Egresados!$O$2:$O$1501,"Residentado")/$I42) | E42: =IF($I42=0,"",COUNTIFS(Egresados!$F$2:$F$1501,$A42,Egresados!$O$2:$O$1501,"Gestión o docencia en salud")/$I42) | F42: =IF($I42=0,"",COUNTIFS(Egresados!$F$2:$F$1501,$A42,Egresados!$O$2:$O$1501,"Otra área")/$I42) | G42: =IF($I42=0,"",COUNTIFS(Egresados!$F$2:$F$1501,$A42,Egresados!$O$2:$O$1501,"Posgrado sin laborar")/$I42) | H42: =IF($I42=0,"",COUNTIFS(Egresados!$F$2:$F$1501,$A42,Egresados!$O$2:$O$1501,"Sin empleo")/$I42) | I42: =COUNTIFS(Egresados!$F$2:$F$1501,$A42,Egresados!$O$2:$O$1501,"<>Sin información",Egresados!$O$2:$O$1501,"<>") -> 0 | J42: =COUNTIFS(Egresados!$F$2:$F$1501,$A42,Egresados!$O$2:$O$1501,"Sin información") -> 0
A43: 2022-I | B43: =IF($I43=0,"",COUNTIFS(Egresados!$F$2:$F$1501,$A43,Egresados!$O$2:$O$1501,"Asistencial")/$I43) -> 0.58064516 | C43: =IF($I43=0,"",COUNTIFS(Egresados!$F$2:$F$1501,$A43,Egresados!$O$2:$O$1501,"SERUMS")/$I43) -> 0 | D43: =IF($I43=0,"",COUNTIFS(Egresados!$F$2:$F$1501,$A43,Egresados!$O$2:$O$1501,"Residentado")/$I43) -> 0.096774194 | E43: =IF($I43=0,"",COUNTIFS(Egresados!$F$2:$F$1501,$A43,Egresados!$O$2:$O$1501,"Gestión o docencia en salud")/$I43) -> 0.032258065 | F43: =IF($I43=0,"",COUNTIFS(Egresados!$F$2:$F$1501,$A43,Egresados!$O$2:$O$1501,"Otra área")/$I43) -> 0 | G43: =IF($I43=0,"",COUNTIFS(Egresados!$F$2:$F$1501,$A43,Egresados!$O$2:$O$1501,"Posgrado sin laborar")/$I43) -> 0 | H43: =IF($I43=0,"",COUNTIFS(Egresados!$F$2:$F$1501,$A43,Egresados!$O$2:$O$1501,"Sin empleo")/$I43) -> 0.29032258 | I43: =COUNTIFS(Egresados!$F$2:$F$1501,$A43,Egresados!$O$2:$O$1501,"<>Sin información",Egresados!$O$2:$O$1501,"<>") -> 31 | J43: =COUNTIFS(Egresados!$F$2:$F$1501,$A43,Egresados!$O$2:$O$1501,"Sin información") -> 28
A44: 2022-II | B44: =IF($I44=0,"",COUNTIFS(Egresados!$F$2:$F$1501,$A44,Egresados!$O$2:$O$1501,"Asistencial")/$I44) -> 0.5 | C44: =IF($I44=0,"",COUNTIFS(Egresados!$F$2:$F$1501,$A44,Egresados!$O$2:$O$1501,"SERUMS")/$I44) -> 0 | D44: =IF($I44=0,"",COUNTIFS(Egresados!$F$2:$F$1501,$A44,Egresados!$O$2:$O$1501,"Residentado")/$I44) -> 0 | E44: =IF($I44=0,"",COUNTIFS(Egresados!$F$2:$F$1501,$A44,Egresados!$O$2:$O$1501,"Gestión o docencia en salud")/$I44) -> 0 | F44: =IF($I44=0,"",COUNTIFS(Egresados!$F$2:$F$1501,$A44,Egresados!$O$2:$O$1501,"Otra área")/$I44) -> 0 | G44: =IF($I44=0,"",COUNTIFS(Egresados!$F$2:$F$1501,$A44,Egresados!$O$2:$O$1501,"Posgrado sin laborar")/$I44) -> 0 | H44: =IF($I44=0,"",COUNTIFS(Egresados!$F$2:$F$1501,$A44,Egresados!$O$2:$O$1501,"Sin empleo")/$I44) -> 0.5 | I44: =COUNTIFS(Egresados!$F$2:$F$1501,$A44,Egresados!$O$2:$O$1501,"<>Sin información",Egresados!$O$2:$O$1501,"<>") -> 2 | J44: =COUNTIFS(Egresados!$F$2:$F$1501,$A44,Egresados!$O$2:$O$1501,"Sin información") -> 95
... A54: 2027-II | B54: =IF($I54=0,"",COUNTIFS(Egresados!$F$2:$F$1501,$A54,Egresados!$O$2:$O$1501,"Asistencial")/$I54) | C54: =IF($I54=0,"",COUNTIFS(Egresados!$F$2:$F$1501,$A54,Egresados!$O$2:$O$1501,"SERUMS")/$I54) | D54: =IF($I54=0,"",COUNTIFS(Egresados!$F$2:$F$1501,$A54,Egresados!$O$2:$O$1501,"Residentado")/$I54) | E54: =IF($I54=0,"",COUNTIFS(Egresados!$F$2:$F$1501,$A54,Egresados!$O$2:$O$1501,"Gestión o docencia en salud")/$I54) | F54: =IF($I54=0,"",COUNTIFS(Egresados!$F$2:$F$1501,$A54,Egresados!$O$2:$O$1501,"Otra área")/$I54) | G54: =IF($I54=0,"",COUNTIFS(Egresados!$F$2:$F$1501,$A54,Egresados!$O$2:$O$1501,"Posgrado sin laborar")/$I54) | H54: =IF($I54=0,"",COUNTIFS(Egresados!$F$2:$F$1501,$A54,Egresados!$O$2:$O$1501,"Sin empleo")/$I54) | I54: =COUNTIFS(Egresados!$F$2:$F$1501,$A54,Egresados!$O$2:$O$1501,"<>Sin información",Egresados!$O$2:$O$1501,"<>") -> 0 | J54: =COUNTIFS(Egresados!$F$2:$F$1501,$A54,Egresados!$O$2:$O$1501,"Sin información") -> 0

Sheet Egresados
A1: ID | B1: Código universitario | C1: Apellidos y nombres | D1: Sexo | E1: Sede | F1: Semestre de egreso | G1: Fecha de egreso | H1: Años desde egreso | I1: Tramo | J1: Condición académica | K1: N.° CMP | L1: Correo | M1: Celular | N1: Ciudad de residencia | O1: Situación laboral | P1: Con empleo | Q1: En su especialidad | R1: Cargo / puesto | S1: ID empleador | T1: Empleador | U1: Datos actualizados en el semestre | V1: Fecha última actualización | W1: Encuesta F1-SSEG-01 respondida | X1: Satisfacción perfil de egreso (1–5) | Y1: Participa en actividades / asociación | Z1: Observaciones | AA1: SERUMS (último dato) | AB1: Fuente de actualización
A2: 1 | B2: 010101145C | C2: AMADO GALIANO MARIA DEL CARMEN | D2: F | E2: Cusco | F2: 2017-II | G2: 43137 | H2: =IF(G2="","",ROUND((Config!$C$4-G2)/365.25,2)) -> 8.65 | I2: =IF(H2="","",IF(H2<=1,"Tramo 1",IF(H2<=3,"Tramo 2",IF(H2<=5,"Tramo 3","Tramo 4")))) -> Tramo 4 | J2: Titulado | L2: carmencitaama@gmail.com | M2: 984933052 | O2: Sin información | P2: =IF(OR(O2="",O2="Sin información"),"",IFERROR(INDEX(Listas!$B$2:$B$9,MATCH(O2,Listas!$A$2:$A$9,0)),"")) | Q2: =IF(OR(O2="",O2="Sin información"),"",IFERROR(INDEX(Listas!$C$2:$C$9,MATCH(O2,Listas!$A$2:$A$9,0)),"")) | T2: =IF(S2="","",IFERROR(INDEX(Empleadores!$B$2:$B$601,MATCH(S2,Empleadores!$A$2:$A$601,0)),"No encontrado")) | U2: =IF(C2="","",IF(V2="","No",IF(Config!$C$4-V2<=Config!$C$15,"Sí","No"))) -> No
A3: 2 | B3: 010200048F | C3: ARROYO ENRIQUEZ LIZ KATHERINE | D3: F | E3: Cusco | F3: 2017-II | G3: 43137 | H3: =IF(G3="","",ROUND((Config!$C$4-G3)/365.25,2)) -> 8.65 | I3: =IF(H3="","",IF(H3<=1,"Tramo 1",IF(H3<=3,"Tramo 2",IF(H3<=5,"Tramo 3","Tramo 4")))) -> Tramo 4 | J3: Titulado | L3: lizarroyoenriquez@hotmail.com | M3: 927665525 | O3: Sin información | P3: =IF(OR(O3="",O3="Sin información"),"",IFERROR(INDEX(Listas!$B$2:$B$9,MATCH(O3,Listas!$A$2:$A$9,0)),"")) | Q3: =IF(OR(O3="",O3="Sin información"),"",IFERROR(INDEX(Listas!$C$2:$C$9,MATCH(O3,Listas!$A$2:$A$9,0)),"")) | T3: =IF(S3="","",IFERROR(INDEX(Empleadores!$B$2:$B$601,MATCH(S3,Empleadores!$A$2:$A$601,0)),"No encontrado")) | U3: =IF(C3="","",IF(V3="","No",IF(Config!$C$4-V3<=Config!$C$15,"Sí","No"))) -> No
A4: 3 | B4: 010200049B | C4: BEJAR CHAUCA JOSE CARLOS | D4: M | E4: Cusco | F4: 2017-II | G4: 43137 | H4: =IF(G4="","",ROUND((Config!$C$4-G4)/365.25,2)) -> 8.65 | I4: =IF(H4="","",IF(H4<=1,"Tramo 1",IF(H4<=3,"Tramo 2",IF(H4<=5,"Tramo 3","Tramo 4")))) -> Tramo 4 | J4: Titulado | L4: jose_stricker@hotmail.com | M4: 926063485 | O4: Sin información | P4: =IF(OR(O4="",O4="Sin información"),"",IFERROR(INDEX(Listas!$B$2:$B$9,MATCH(O4,Listas!$A$2:$A$9,0)),"")) | Q4: =IF(OR(O4="",O4="Sin información"),"",IFERROR(INDEX(Listas!$C$2:$C$9,MATCH(O4,Listas!$A$2:$A$9,0)),"")) | T4: =IF(S4="","",IFERROR(INDEX(Empleadores!$B$2:$B$601,MATCH(S4,Empleadores!$A$2:$A$601,0)),"No encontrado")) | U4: =IF(C4="","",IF(V4="","No",IF(Config!$C$4-V4<=Config!$C$15,"Sí","No"))) -> No
A5: 4 | B5: 010101149I | C5: CABRERA BERROCAL ROMULO ABRAHAM | D5: M | E5: Cusco | F5: 2017-II | G5: 43137 | H5: =IF(G5="","",ROUND((Config!$C$4-G5)/365.25,2)) -> 8.65 | I5: =IF(H5="","",IF(H5<=1,"Tramo 1",IF(H5<=3,"Tramo 2",IF(H5<=5,"Tramo 3","Tramo 4")))) -> Tramo 4 | J5: Titulado | L5: abrahamrcb@hotmail.com | M5: 941555739 | O5: Sin información | P5: =IF(OR(O5="",O5="Sin información"),"",IFERROR(INDEX(Listas!$B$2:$B$9,MATCH(O5,Listas!$A$2:$A$9,0)),"")) | Q5: =IF(OR(O5="",O5="Sin información"),"",IFERROR(INDEX(Listas!$C$2:$C$9,MATCH(O5,Listas!$A$2:$A$9,0)),"")) | T5: =IF(S5="","",IFERROR(INDEX(Empleadores!$B$2:$B$601,MATCH(S5,Empleadores!$A$2:$A$601,0)),"No encontrado")) | U5: =IF(C5="","",IF(V5="","No",IF(Config!$C$4-V5<=Config!$C$15,"Sí","No"))) -> No
A6: 5 | B6: 010200051G | C6: CARDENAS APAZA GIULIANA BRIGITTE | D6: F | E6: Cusco | F6: 2017-II | G6: 43137 | H6: =IF(G6="","",ROUND((Config!$C$4-G6)/365.25,2)) -> 8.65 | I6: =IF(H6="","",IF(H6<=1,"Tramo 1",IF(H6<=3,"Tramo 2",IF(H6<=5,"Tramo 3","Tramo 4")))) -> Tramo 4 | J6: Titulado | L6: GIBRITTE_8@HOTMAIL.COM | M6: 987311309 | O6: Sin información | P6: =IF(OR(O6="",O6="Sin información"),"",IFERROR(INDEX(Listas!$B$2:$B$9,MATCH(O6,Listas!$A$2:$A$9,0)),"")) | Q6: =IF(OR(O6="",O6="Sin información"),"",IFERROR(INDEX(Listas!$C$2:$C$9,MATCH(O6,Listas!$A$2:$A$9,0)),"")) | T6: =IF(S6="","",IFERROR(INDEX(Empleadores!$B$2:$B$601,MATCH(S6,Empleadores!$A$2:$A$601,0)),"No encontrado")) | U6: =IF(C6="","",IF(V6="","No",IF(Config!$C$4-V6<=Config!$C$15,"Sí","No"))) -> No
A7: 6 | B7: 011200687H | C7: CASTAÑEDA MONTAÑEZ JOSEPH ABELARDO | D7: M | E7: Cusco | F7: 2017-II | G7: 43137 | H7: =IF(G7="","",ROUND((Config!$C$4-G7)/365.25,2)) -> 8.65 | I7: =IF(H7="","",IF(H7<=1,"Tramo 1",IF(H7<=3,"Tramo 2",IF(H7<=5,"Tramo 3","Tramo 4")))) -> Tramo 4 | J7: Titulado | L7: joseph_10717@hotmail.com | M7: 974673666 | O7: Sin información | P7: =IF(OR(O7="",O7="Sin información"),"",IFERROR(INDEX(Listas!$B$2:$B$9,MATCH(O7,Listas!$A$2:$A$9,0)),"")) | Q7: =IF(OR(O7="",O7="Sin información"),"",IFERROR(INDEX(Listas!$C$2:$C$9,MATCH(O7,Listas!$A$2:$A$9,0)),"")) | T7: =IF(S7="","",IFERROR(INDEX(Empleadores!$B$2:$B$601,MATCH(S7,Empleadores!$A$2:$A$601,0)),"No encontrado")) | U7: =IF(C7="","",IF(V7="","No",IF(Config!$C$4-V7<=Config!$C$15,"Sí","No"))) -> No
A8: 7 | B8: 010101151C | C8: CONTRERAS PIZARRO MARX | D8: M | E8: Cusco | F8: 2017-II | G8: 43137 | H8: =IF(G8="","",ROUND((Config!$C$4-G8)/365.25,2)) -> 8.65 | I8: =IF(H8="","",IF(H8<=1,"Tramo 1",IF(H8<=3,"Tramo 2",IF(H8<=5,"Tramo 3","Tramo 4")))) -> Tramo 4 | J8: Bachiller | L8: marxcp_1@hotmail.com | M8: 973675813 | O8: Sin información | P8: =IF(OR(O8="",O8="Sin información"),"",IFERROR(INDEX(Listas!$B$2:$B$9,MATCH(O8,Listas!$A$2:$A$9,0)),"")) | Q8: =IF(OR(O8="",O8="Sin información"),"",IFERROR(INDEX(Listas!$C$2:$C$9,MATCH(O8,Listas!$A$2:$A$9,0)),"")) | T8: =IF(S8="","",IFERROR(INDEX(Empleadores!$B$2:$B$601,MATCH(S8,Empleadores!$A$2:$A$601,0)),"No encontrado")) | U8: =IF(C8="","",IF(V8="","No",IF(Config!$C$4-V8<=Config!$C$15,"Sí","No"))) -> No
A9: 8 | B9: 010200054F | C9: CUSIPAUCAR USCAMAITA GUSTAVO | D9: M | E9: Cusco | F9: 2017-II | G9: 43137 | H9: =IF(G9="","",ROUND((Config!$C$4-G9)/365.25,2)) -> 8.65 | I9: =IF(H9="","",IF(H9<=1,"Tramo 1",IF(H9<=3,"Tramo 2",IF(H9<=5,"Tramo 3","Tramo 4")))) -> Tramo 4 | J9: Titulado | L9: gus7209@hotmail.com | M9: 941001533 | O9: Sin información | P9: =IF(OR(O9="",O9="Sin información"),"",IFERROR(INDEX(Listas!$B$2:$B$9,MATCH(O9,Listas!$A$2:$A$9,0)),"")) | Q9: =IF(OR(O9="",O9="Sin información"),"",IFERROR(INDEX(Listas!$C$2:$C$9,MATCH(O9,Listas!$A$2:$A$9,0)),"")) | T9: =IF(S9="","",IFERROR(INDEX(Empleadores!$B$2:$B$601,MATCH(S9,Empleadores!$A$2:$A$601,0)),"No encontrado")) | U9: =IF(C9="","",IF(V9="","No",IF(Config!$C$4-V9<=Config!$C$15,"Sí","No"))) -> No
A10: 9 | B10: 010101154B | C10: DIAZ FLOREZ VICTOR IVANNY | D10: M | E10: Cusco | F10: 2017-II | G10: 43137 | H10: =IF(G10="","",ROUND((Config!$C$4-G10)/365.25,2)) -> 8.65 | I10: =IF(H10="","",IF(H10<=1,"Tramo 1",IF(H10<=3,"Tramo 2",IF(H10<=5,"Tramo 3","Tramo 4")))) -> Tramo 4 | J10: Titulado | L10: vitovanny@gmail.com | M10: 993609625 | O10: Sin información | P10: =IF(OR(O10="",O10="Sin información"),"",IFERROR(INDEX(Listas!$B$2:$B$9,MATCH(O10,Listas!$A$2:$A$9,0)),"")) | Q10: =IF(OR(O10="",O10="Sin información"),"",IFERROR(INDEX(Listas!$C$2:$C$9,MATCH(O10,Listas!$A$2:$A$9,0)),"")) | T10: =IF(S10="","",IFERROR(INDEX(Empleadores!$B$2:$B$601,MATCH(S10,Empleadores!$A$2:$A$601,0)),"No encontrado")) | U10: =IF(C10="","",IF(V10="","No",IF(Config!$C$4-V10<=Config!$C$15,"Sí","No"))) -> No
A11: 10 | B11: 010200055B | C11: ERQUINIGO MARTINEZ RUSS MERY | D11: F | E11: Cusco | F11: 2017-II | G11: 43137 | H11: =IF(G11="","",ROUND((Config!$C$4-G11)/365.25,2)) -> 8.65 | I11: =IF(H11="","",IF(H11<=1,"Tramo 1",IF(H11<=3,"Tramo 2",IF(H11<=5,"Tramo 3","Tramo 4")))) -> Tramo 4 | J11: Titulado | L11: vitovanny@gmail.com | M11: 966565152 | O11: Asistencial | P11: =IF(OR(O11="",O11="Sin información"),"",IFERROR(INDEX(Listas!$B$2:$B$9,MATCH(O11,Listas!$A$2:$A$9,0)),"")) -> Sí | Q11: =IF(OR(O11="",O11="Sin información"),"",IFERROR(INDEX(Listas!$C$2:$C$9,MATCH(O11,Listas!$A$2:$A$9,0)),"")) -> Sí | S11: EMP-001 | T11: =IF(S11="","",IFERROR(INDEX(Empleadores!$B$2:$B$601,MATCH(S11,Empleadores!$A$2:$A$601,0)),"No encontrado")) -> Hospital Regional del Cusco | U11: =IF(C11="","",IF(V11="","No",IF(Config!$C$4-V11<=Config!$C$15,"Sí","No"))) -> Sí | V11: 45974 | Y11: Sí | Z11: Marcó 'Otros' en el Encuentro: verificar si es residentado | AB11: I Encuentro de Egresados
A12: 11 | B12: 010101156E | C12: ESENARRO MEZA FRANCO MARTIN | D12: M | E12: Cusco | F12: 2017-II | G12: 43137 | H12: =IF(G12="","",ROUND((Config!$C$4-G12)/365.25,2)) -> 8.65 | I12: =IF(H12="","",IF(H12<=1,"Tramo 1",IF(H12<=3,"Tramo 2",IF(H12<=5,"Tramo 3","Tramo 4")))) -> Tramo 4 | J12: Titulado | L12: francoesenarro@gmail.com | M12: 984162624 | O12: Sin información | P12: =IF(OR(O12="",O12="Sin información"),"",IFERROR(INDEX(Listas!$B$2:$B$9,MATCH(O12,Listas!$A$2:$A$9,0)),"")) | Q12: =IF(OR(O12="",O12="Sin información"),"",IFERROR(INDEX(Listas!$C$2:$C$9,MATCH(O12,Listas!$A$2:$A$9,0)),"")) | T12: =IF(S12="","",IFERROR(INDEX(Empleadores!$B$2:$B$601,MATCH(S12,Empleadores!$A$2:$A$601,0)),"No encontrado")) | U12: =IF(C12="","",IF(V12="","No",IF(Config!$C$4-V12<=Config!$C$15,"Sí","No"))) -> No
A13: 12 | B13: 010200056I | C13: ESPEJO ALENCASTRE CIRO BRYAN | D13: M | E13: Cusco | F13: 2017-II | G13: 43137 | H13: =IF(G13="","",ROUND((Config!$C$4-G13)/365.25,2)) -> 8.65 | I13: =IF(H13="","",IF(H13<=1,"Tramo 1",IF(H13<=3,"Tramo 2",IF(H13<=5,"Tramo 3","Tramo 4")))) -> Tramo 4 | J13: Titulado | L13: bryanespejosc4@hotmail.com | M13: 987879717 | O13: Sin información | P13: =IF(OR(O13="",O13="Sin información"),"",IFERROR(INDEX(Listas!$B$2:$B$9,MATCH(O13,Listas!$A$2:$A$9,0)),"")) | Q13: =IF(OR(O13="",O13="Sin información"),"",IFERROR(INDEX(Listas!$C$2:$C$9,MATCH(O13,Listas!$A$2:$A$9,0)),"")) | T13: =IF(S13="","",IFERROR(INDEX(Empleadores!$B$2:$B$601,MATCH(S13,Empleadores!$A$2:$A$601,0)),"No encontrado")) | U13: =IF(C13="","",IF(V13="","No",IF(Config!$C$4-V13<=Config!$C$15,"Sí","No"))) -> No
A14: 13 | B14: 010200057E | C14: ESTRADA GUTIERREZ KARLA STEFANY | D14: F | E14: Cusco | F14: 2017-II | G14: 43137 | H14: =IF(G14="","",ROUND((Config!$C$4-G14)/365.25,2)) -> 8.65 | I14: =IF(H14="","",IF(H14<=1,"Tramo 1",IF(H14<=3,"Tramo 2",IF(H14<=5,"Tramo 3","Tramo 4")))) -> Tramo 4 | J14: Titulado | L14: tefy_xd@hotmail.com | M14: 974783160 | O14: Sin información | P14: =IF(OR(O14="",O14="Sin información"),"",IFERROR(INDEX(Listas!$B$2:$B$9,MATCH(O14,Listas!$A$2:$A$9,0)),"")) | Q14: =IF(OR(O14="",O14="Sin información"),"",IFERROR(INDEX(Listas!$C$2:$C$9,MATCH(O14,Listas!$A$2:$A$9,0)),"")) | T14: =IF(S14="","",IFERROR(INDEX(Empleadores!$B$2:$B$601,MATCH(S14,Empleadores!$A$2:$A$601,0)),"No encontrado")) | U14: =IF(C14="","",IF(V14="","No",IF(Config!$C$4-V14<=Config!$C$15,"Sí","No"))) -> No
A15: 14 | B15: 010200059H | C15: FERNANDEZ BRAVO ANGELA MILAGROS | D15: F | E15: Cusco | F15: 2017-II | G15: 43137 | H15: =IF(G15="","",ROUND((Config!$C$4-G15)/365.25,2)) -> 8.65 | I15: =IF(H15="","",IF(H15<=1,"Tramo 1",IF(H15<=3,"Tramo 2",IF(H15<=5,"Tramo 3","Tramo 4")))) -> Tramo 4 | J15: Titulado | L15: angiemfb@gmail.com | M15: 961165505 | O15: Sin información | P15: =IF(OR(O15="",O15="Sin información"),"",IFERROR(INDEX(Listas!$B$2:$B$9,MATCH(O15,Listas!$A$2:$A$9,0)),"")) | Q15: =IF(OR(O15="",O15="Sin información"),"",IFERROR(INDEX(Listas!$C$2:$C$9,MATCH(O15,Listas!$A$2:$A$9,0)),"")) | T15: =IF(S15="","",IFERROR(INDEX(Empleadores!$B$2:$B$601,MATCH(S15,Empleadores!$A$2:$A$601,0)),"No encontrado")) | U15: =IF(C15="","",IF(V15="","No",IF(Config!$C$4-V15<=Config!$C$15,"Sí","No"))) -> No
A16: 15 | B16: 011200684I | C16: GALINDO GUEVARA MARGIORI | D16: F | E16: Cusco | F16: 2017-II | G16: 43137 | H16: =IF(G16="","",ROUND((Config!$C$4-G16)/365.25,2)) -> 8.65 | I16: =IF(H16="","",IF(H16<=1,"Tramo 1",IF(H16<=3,"Tramo 2",IF(H16<=5,"Tramo 3","Tramo 4")))) -> Tramo 4 | J16: Titulado | L16: margie_257@hotmail.com | M16: 984445832 | O16: Sin información | P16: =IF(OR(O16="",O16="Sin información"),"",IFERROR(INDEX(Listas!$B$2:$B$9,MATCH(O16,Listas!$A$2:$A$9,0)),"")) | Q16: =IF(OR(O16="",O16="Sin información"),"",IFERROR(INDEX(Listas!$C$2:$C$9,MATCH(O16,Listas!$A$2:$A$9,0)),"")) | T16: =IF(S16="","",IFERROR(INDEX(Empleadores!$B$2:$B$601,MATCH(S16,Empleadores!$A$2:$A$601,0)),"No encontrado")) | U16: =IF(C16="","",IF(V16="","No",IF(Config!$C$4-V16<=Config!$C$15,"Sí","No"))) -> No
A17: 16 | B17: 011100435G | C17: GARCIA SAMANEZ ALYTSA MARICLE | D17: F | E17: Cusco | F17: 2017-II | G17: 43137 | H17: =IF(G17="","",ROUND((Config!$C$4-G17)/365.25,2)) -> 8.65 | I17: =IF(H17="","",IF(H17<=1,"Tramo 1",IF(H17<=3,"Tramo 2",IF(H17<=5,"Tramo 3","Tramo 4")))) -> Tramo 4 | J17: Titulado | L17: alytsa_1799@hotmail.com | M17: 984831939 | O17: Sin información | P17: =IF(OR(O17="",O17="Sin información"),"",IFERROR(INDEX(Listas!$B$2:$B$9,MATCH(O17,Listas!$A$2:$A$9,0)),"")) | Q17: =IF(OR(O17="",O17="Sin información"),"",IFERROR(INDEX(Listas!$C$2:$C$9,MATCH(O17,Listas!$A$2:$A$9,0)),"")) | T17: =IF(S17="","",IFERROR(INDEX(Empleadores!$B$2:$B$601,MATCH(S17,Empleadores!$A$2:$A$601,0)),"No encontrado")) | U17: =IF(C17="","",IF(V17="","No",IF(Config!$C$4-V17<=Config!$C$15,"Sí","No"))) -> No
A18: 17 | B18: 011100436C | C18: GUTIERREZ VENERO ELIO SERGIO | D18: M | E18: Cusco | F18: 2017-II | G18: 43137 | H18: =IF(G18="","",ROUND((Config!$C$4-G18)/365.25,2)) -> 8.65 | I18: =IF(H18="","",IF(H18<=1,"Tramo 1",IF(H18<=3,"Tramo 2",IF(H18<=5,"Tramo 3","Tramo 4")))) -> Tramo 4 | J18: Titulado | L18: sergi_guti@hotmail.com | M18: 993082414 | O18: Sin información | P18: =IF(OR(O18="",O18="Sin información"),"",IFERROR(INDEX(Listas!$B$2:$B$9,MATCH(O18,Listas!$A$2:$A$9,0)),"")) | Q18: =IF(OR(O18="",O18="Sin información"),"",IFERROR(INDEX(Listas!$C$2:$C$9,MATCH(O18,Listas!$A$2:$A$9,0)),"")) | T18: =IF(S18="","",IFERROR(INDEX(Empleadores!$B$2:$B$601,MATCH(S18,Empleadores!$A$2:$A$601,0)),"No encontrado")) | U18: =IF(C18="","",IF(V18="","No",IF(Config!$C$4-V18<=Config!$C$15,"Sí","No"))) -> No
A19: 18 | B19: 011100438F | C19: HALANOCA QUISPE CARINA | D19: F | E19: Cusco | F19: 2017-II | G19: 43137 | H19: =IF(G19="","",ROUND((Config!$C$4-G19)/365.25,2)) -> 8.65 | I19: =IF(H19="","",IF(H19<=1,"Tramo 1",IF(H19<=3,"Tramo 2",IF(H19<=5,"Tramo 3","Tramo 4")))) -> Tramo 4 | J19: Titulado | L19: cahaqui120@gmail.com | M19: 942244414 | O19: Sin información | P19: =IF(OR(O19="",O19="Sin información"),"",IFERROR(INDEX(Listas!$B$2:$B$9,MATCH(O19,Listas!$A$2:$A$9,0)),"")) | Q19: =IF(OR(O19="",O19="Sin información"),"",IFERROR(INDEX(Listas!$C$2:$C$9,MATCH(O19,Listas!$A$2:$A$9,0)),"")) | T19: =IF(S19="","",IFERROR(INDEX(Empleadores!$B$2:$B$601,MATCH(S19,Empleadores!$A$2:$A$601,0)),"No encontrado")) | U19: =IF(C19="","",IF(V19="","No",IF(Config!$C$4-V19<=Config!$C$15,"Sí","No"))) -> No
A20: 19 | B20: 011100439B | C20: HERRERA BUSTAMANTE TATIANA CELINA | D20: F | E20: Cusco | F20: 2017-II | G20: 43137 | H20: =IF(G20="","",ROUND((Config!$C$4-G20)/365.25,2)) -> 8.65 | I20: =IF(H20="","",IF(H20<=1,"Tramo 1",IF(H20<=3,"Tramo 2",IF(H20<=5,"Tramo 3","Tramo 4")))) -> Tramo 4 | J20: Titulado | L20: celinahb1@gmail.com | M20: 972763114 | O20: Sin información | P20: =IF(OR(O20="",O20="Sin información"),"",IFERROR(INDEX(Listas!$B$2:$B$9,MATCH(O20,Listas!$A$2:$A$9,0)),"")) | Q20: =IF(OR(O20="",O20="Sin información"),"",IFERROR(INDEX(Listas!$C$2:$C$9,MATCH(O20,Listas!$A$2:$A$9,0)),"")) | T20: =IF(S20="","",IFERROR(INDEX(Empleadores!$B$2:$B$601,MATCH(S20,Empleadores!$A$2:$A$601,0)),"No encontrado")) | U20: =IF(C20="","",IF(V20="","No",IF(Config!$C$4-V20<=Config!$C$15,"Sí","No"))) -> No
A21: 20 | B21: 010101158H | C21: HUALLPAYUNCA PILLCO KAREN SABY | D21: F | E21: Cusco | F21: 2017-II | G21: 43137 | H21: =IF(G21="","",ROUND((Config!$C$4-G21)/365.25,2)) -> 8.65 | I21: =IF(H21="","",IF(H21<=1,"Tramo 1",IF(H21<=3,"Tramo 2",IF(H21<=5,"Tramo 3","Tramo 4")))) -> Tramo 4 | J21: Titulado | L21: rnhpillco@gmail.com | M21: 986198960 | O21: Sin información | P21: =IF(OR(O21="",O21="Sin información"),"",IFERROR(INDEX(Listas!$B$2:$B$9,MATCH(O21,Listas!$A$2:$A$9,0)),"")) | Q21: =IF(OR(O21="",O21="Sin información"),"",IFERROR(INDEX(Listas!$C$2:$C$9,MATCH(O21,Listas!$A$2:$A$9,0)),"")) | T21: =IF(S21="","",IFERROR(INDEX(Empleadores!$B$2:$B$601,MATCH(S21,Empleadores!$A$2:$A$601,0)),"No encontrado")) | U21: =IF(C21="","",IF(V21="","No",IF(Config!$C$4-V21<=Config!$C$15,"Sí","No"))) -> No
A22: 21 | B22: 010101159D | C22: HUAMAN APAZA HILDA MAYRA | D22: F | E22: Cusco | F22: 2017-II | G22: 43137 | H22: =IF(G22="","",ROUND((Config!$C$4-G22)/365.25,2)) -> 8.65 | I22: =IF(H22="","",IF(H22<=1,"Tramo 1",IF(H22<=3,"Tramo 2",IF(H22<=5,"Tramo 3","Tramo 4")))) -> Tramo 4 | J22: Titulado | L22: yarimalda_100@outlook.com | M22: 979315464 | O22: Asistencial | P22: =IF(OR(O22="",O22="Sin información"),"",IFERROR(INDEX(Listas!$B$2:$B$9,MATCH(O22,Listas!$A$2:$A$9,0)),"")) -> Sí | Q22: =IF(OR(O22="",O22="Sin información"),"",IFERROR(INDEX(Listas!$C$2:$C$9,MATCH(O22,Listas!$A$2:$A$9,0)),"")) -> Sí | S22: EMP-001 | T22: =IF(S22="","",IFERROR(INDEX(Empleadores!$B$2:$B$601,MATCH(S22,Empleadores!$A$2:$A$601,0)),"No encontrado")) -> Hospital Regional del Cusco | U22: =IF(C22="","",IF(V22="","No",IF(Config!$C$4-V22<=Config!$C$15,"Sí","No"))) -> Sí | V22: 45974 | Y22: Sí | AB22: I Encuentro de Egresados
A23: 22 | B23: 011200694D | C23: HUGO CARRILLO JHUVILKA | D23: F | E23: Cusco | F23: 2017-II | G23: 43137 | H23: =IF(G23="","",ROUND((Config!$C$4-G23)/365.25,2)) -> 8.65 | I23: =IF(H23="","",IF(H23<=1,"Tramo 1",IF(H23<=3,"Tramo 2",IF(H23<=5,"Tramo 3","Tramo 4")))) -> Tramo 4 | J23: Titulado | L23: c_lili_2008@hotmail.com | M23: 984235313 | O23: Sin información | P23: =IF(OR(O23="",O23="Sin información"),"",IFERROR(INDEX(Listas!$B$2:$B$9,MATCH(O23,Listas!$A$2:$A$9,0)),"")) | Q23: =IF(OR(O23="",O23="Sin información"),"",IFERROR(INDEX(Listas!$C$2:$C$9,MATCH(O23,Listas!$A$2:$A$9,0)),"")) | T23: =IF(S23="","",IFERROR(INDEX(Empleadores!$B$2:$B$601,MATCH(S23,Empleadores!$A$2:$A$601,0)),"No encontrado")) | U23: =IF(C23="","",IF(V23="","No",IF(Config!$C$4-V23<=Config!$C$15,"Sí","No"))) -> No
A24: 23 | B24: 011100447E | C24: MAMANI VARGAS CHRISTEL GABRIELA | D24: F | E24: Cusco | F24: 2017-II | G24: 43137 | H24: =IF(G24="","",ROUND((Config!$C$4-G24)/365.25,2)) -> 8.65 | I24: =IF(H24="","",IF(H24<=1,"Tramo 1",IF(H24<=3,"Tramo 2",IF(H24<=5,"Tramo 3","Tramo 4")))) -> Tramo 4 | J24: Titulado | L24: christelgabrielamamanivargas@gmail.com | M24: 984378430 | O24: Sin información | P24: =IF(OR(O24="",O24="Sin información"),"",IFERROR(INDEX(Listas!$B$2:$B$9,MATCH(O24,Listas!$A$2:$A$9,0)),"")) | Q24: =IF(OR(O24="",O24="Sin información"),"",IFERROR(INDEX(Listas!$C$2:$C$9,MATCH(O24,Listas!$A$2:$A$9,0)),"")) | T24: =IF(S24="","",IFERROR(INDEX(Empleadores!$B$2:$B$601,MATCH(S24,Empleadores!$A$2:$A$601,0)),"No encontrado")) | U24: =IF(C24="","",IF(V24="","No",IF(Config!$C$4-V24<=Config!$C$15,"Sí","No"))) -> No
A25: 24 | B25: 010101161I | C25: MAR VALER CARLOS | D25: M | E25: Cusco | F25: 2017-II | G25: 43137 | H25: =IF(G25="","",ROUND((Config!$C$4-G25)/365.25,2)) -> 8.65 | I25: =IF(H25="","",IF(H25<=1,"Tramo 1",IF(H25<=3,"Tramo 2",IF(H25<=5,"Tramo 3","Tramo 4")))) -> Tramo 4 | J25: Titulado | L25: calitos199@hotmail.com | M25: 969146031 | O25: Sin información | P25: =IF(OR(O25="",O25="Sin información"),"",IFERROR(INDEX(Listas!$B$2:$B$9,MATCH(O25,Listas!$A$2:$A$9,0)),"")) | Q25: =IF(OR(O25="",O25="Sin información"),"",IFERROR(INDEX(Listas!$C$2:$C$9,MATCH(O25,Listas!$A$2:$A$9,0)),"")) | T25: =IF(S25="","",IFERROR(INDEX(Empleadores!$B$2:$B$601,MATCH(S25,Empleadores!$A$2:$A$601,0)),"No encontrado")) | U25: =IF(C25="","",IF(V25="","No",IF(Config!$C$4-V25<=Config!$C$15,"Sí","No"))) -> No
A26: 25 | B26: 010200063E | C26: MARQUEZ GAMARRA INDHIRA LUCY | D26: F | E26: Cusco | F26: 2017-II | G26: 43137 | H26: =IF(G26="","",ROUND((Config!$C$4-G26)/365.25,2)) -> 8.65 | I26: =IF(H26="","",IF(H26<=1,"Tramo 1",IF(H26<=3,"Tramo 2",IF(H26<=5,"Tramo 3","Tramo 4")))) -> Tramo 4 | J26: Titulado | L26: indhiralucy@gmail.com | M26: 972251100 | O26: Sin información | P26: =IF(OR(O26="",O26="Sin información"),"",IFERROR(INDEX(Listas!$B$2:$B$9,MATCH(O26,Listas!$A$2:$A$9,0)),"")) | Q26: =IF(OR(O26="",O26="Sin información"),"",IFERROR(INDEX(Listas!$C$2:$C$9,MATCH(O26,Listas!$A$2:$A$9,0)),"")) | T26: =IF(S26="","",IFERROR(INDEX(Empleadores!$B$2:$B$601,MATCH(S26,Empleadores!$A$2:$A$601,0)),"No encontrado")) | U26: =IF(C26="","",IF(V26="","No",IF(Config!$C$4-V26<=Config!$C$15,"Sí","No"))) -> No
A27: 26 | B27: 010101165D | C27: OBANDO GAMARRA MIRYAM LISSETH | D27: F | E27: Cusco | F27: 2017-II | G27: 43137 | H27: =IF(G27="","",ROUND((Config!$C$4-G27)/365.25,2)) -> 8.65 | I27: =IF(H27="","",IF(H27<=1,"Tramo 1",IF(H27<=3,"Tramo 2",IF(H27<=5,"Tramo 3","Tramo 4")))) -> Tramo 4 | J27: Titulado | L27: mirylissyo@hotmail.com | M27: 976342775 | O27: Sin información | P27: =IF(OR(O27="",O27="Sin información"),"",IFERROR(INDEX(Listas!$B$2:$B$9,MATCH(O27,Listas!$A$2:$A$9,0)),"")) | Q27: =IF(OR(O27="",O27="Sin información"),"",IFERROR(INDEX(Listas!$C$2:$C$9,MATCH(O27,Listas!$A$2:$A$9,0)),"")) | T27: =IF(S27="","",IFERROR(INDEX(Empleadores!$B$2:$B$601,MATCH(S27,Empleadores!$A$2:$A$601,0)),"No encontrado")) | U27: =IF(C27="","",IF(V27="","No",IF(Config!$C$4-V27<=Config!$C$15,"Sí","No"))) -> No
A28: 27 | B28: 011300770D | C28: ORELLANA ARAUJO KIPLING | D28: M | E28: Cusco | F28: 2017-II | G28: 43137 | H28: =IF(G28="","",ROUND((Config!$C$4-G28)/365.25,2)) -> 8.65 | I28: =IF(H28="","",IF(H28<=1,"Tramo 1",IF(H28<=3,"Tramo 2",IF(H28<=5,"Tramo 3","Tramo 4")))) -> Tramo 4 | J28: Bachiller | L28: koangmh@gmail.com | O28: Sin información | P28: =IF(OR(O28="",O28="Sin información"),"",IFERROR(INDEX(Listas!$B$2:$B$9,MATCH(O28,Listas!$A$2:$A$9,0)),"")) | Q28: =IF(OR(O28="",O28="Sin información"),"",IFERROR(INDEX(Listas!$C$2:$C$9,MATCH(O28,Listas!$A$2:$A$9,0)),"")) | T28: =IF(S28="","",IFERROR(INDEX(Empleadores!$B$2:$B$601,MATCH(S28,Empleadores!$A$2:$A$601,0)),"No encontrado")) | U28: =IF(C28="","",IF(V28="","No",IF(Config!$C$4-V28<=Config!$C$15,"Sí","No"))) -> No
A29: 28 | B29: 010200066D | C29: ORTIZ DE ORUE JURO ALLISON ISABEL | D29: F | E29: Cusco | F29: 2017-II | G29: 43137 | H29: =IF(G29="","",ROUND((Config!$C$4-G29)/365.25,2)) -> 8.65 | I29: =IF(H29="","",IF(H29<=1,"Tramo 1",IF(H29<=3,"Tramo 2",IF(H29<=5,"Tramo 3","Tramo 4")))) -> Tramo 4 | J29: Titulado | L29: allibela.ortizdeorue@gmail.com | M29: 984158092 | O29: Sin información | P29: =IF(OR(O29="",O29="Sin información"),"",IFERROR(INDEX(Listas!$B$2:$B$9,MATCH(O29,Listas!$A$2:$A$9,0)),"")) | Q29: =IF(OR(O29="",O29="Sin información"),"",IFERROR(INDEX(Listas!$C$2:$C$9,MATCH(O29,Listas!$A$2:$A$9,0)),"")) | T29: =IF(S29="","",IFERROR(INDEX(Empleadores!$B$2:$B$601,MATCH(S29,Empleadores!$A$2:$A$601,0)),"No encontrado")) | U29: =IF(C29="","",IF(V29="","No",IF(Config!$C$4-V29<=Config!$C$15,"Sí","No"))) -> No
A30: 29 | B30: 010200068G | C30: PAREDES LAZARO MARYSHEILY | D30: F | E30: Cusco | F30: 2017-II | G30: 43137 | H30: =IF(G30="","",ROUND((Config!$C$4-G30)/365.25,2)) -> 8.65 | I30: =IF(H30="","",IF(H30<=1,"Tramo 1",IF(H30<=3,"Tramo 2",IF(H30<=5,"Tramo 3","Tramo 4")))) -> Tramo 4 | J30: Titulado | L30: MARYSHEILYPAREDESLAZARO@GMAIL.COM | M30: 929016288 | O30: Sin información | P30: =IF(OR(O30="",O30="Sin información"),"",IFERROR(INDEX(Listas!$B$2:$B$9,MATCH(O30,Listas!$A$2:$A$9,0)),"")) | Q30: =IF(OR(O30="",O30="Sin información"),"",IFERROR(INDEX(Listas!$C$2:$C$9,MATCH(O30,Listas!$A$2:$A$9,0)),"")) | T30: =IF(S30="","",IFERROR(INDEX(Empleadores!$B$2:$B$601,MATCH(S30,Empleadores!$A$2:$A$601,0)),"No encontrado")) | U30: =IF(C30="","",IF(V30="","No",IF(Config!$C$4-V30<=Config!$C$15,"Sí","No"))) -> No
A31: 30 | B31: 010101169J | C31: PEREIRA VICTORIO KEVIN AUGUSTINE | D31: M | E31: Cusco | F31: 2017-II | G31: 43137 | H31: =IF(G31="","",ROUND((Config!$C$4-G31)/365.25,2)) -> 8.65 | I31: =IF(H31="","",IF(H31<=1,"Tramo 1",IF(H31<=3,"Tramo 2",IF(H31<=5,"Tramo 3","Tramo 4")))) -> Tramo 4 | J31: Titulado | L31: kevin.pereira.victorio@gmail.com | M31: 979711799 | O31: Sin información | P31: =IF(OR(O31="",O31="Sin información"),"",IFERROR(INDEX(Listas!$B$2:$B$9,MATCH(O31,Listas!$A$2:$A$9,0)),"")) | Q31: =IF(OR(O31="",O31="Sin información"),"",IFERROR(INDEX(Listas!$C$2:$C$9,MATCH(O31,Listas!$A$2:$A$9,0)),"")) | T31: =IF(S31="","",IFERROR(INDEX(Empleadores!$B$2:$B$601,MATCH(S31,Empleadores!$A$2:$A$601,0)),"No encontrado")) | U31: =IF(C31="","",IF(V31="","No",IF(Config!$C$4-V31<=Config!$C$15,"Sí","No"))) -> No
A32: 31 | B32: 010200069C | C32: PEREZ QUISPE ANA RUBI | D32: F | E32: Cusco | F32: 2017-II | G32: 43137 | H32: =IF(G32="","",ROUND((Config!$C$4-G32)/365.25,2)) -> 8.65 | I32: =IF(H32="","",IF(H32<=1,"Tramo 1",IF(H32<=3,"Tramo 2",IF(H32<=5,"Tramo 3","Tramo 4")))) -> Tramo 4 | J32: Titulado | L32: anarubip@gmail.com | M32: 982518282 | O32: Sin información | P32: =IF(OR(O32="",O32="Sin información"),"",IFERROR(INDEX(Listas!$B$2:$B$9,MATCH(O32,Listas!$A$2:$A$9,0)),"")) | Q32: =IF(OR(O32="",O32="Sin información"),"",IFERROR(INDEX(Listas!$C$2:$C$9,MATCH(O32,Listas!$A$2:$A$9,0)),"")) | T32: =IF(S32="","",IFERROR(INDEX(Empleadores!$B$2:$B$601,MATCH(S32,Empleadores!$A$2:$A$601,0)),"No encontrado")) | U32: =IF(C32="","",IF(V32="","No",IF(Config!$C$4-V32<=Config!$C$15,"Sí","No"))) -> No
A33: 32 | B33: 010200071H | C33: PUMA SUSANO JOSE LUIS | D33: M | E33: Cusco | F33: 2017-II | G33: 43137 | H33: =IF(G33="","",ROUND((Config!$C$4-G33)/365.25,2)) -> 8.65 | I33: =IF(H33="","",IF(H33<=1,"Tramo 1",IF(H33<=3,"Tramo 2",IF(H33<=5,"Tramo 3","Tramo 4")))) -> Tramo 4 | J33: Titulado | L33: luisino_luis@hotmail.com | M33: 950313949 | O33: Sin información | P33: =IF(OR(O33="",O33="Sin información"),"",IFERROR(INDEX(Listas!$B$2:$B$9,MATCH(O33,Listas!$A$2:$A$9,0)),"")) | Q33: =IF(OR(O33="",O33="Sin información"),"",IFERROR(INDEX(Listas!$C$2:$C$9,MATCH(O33,Listas!$A$2:$A$9,0)),"")) | T33: =IF(S33="","",IFERROR(INDEX(Empleadores!$B$2:$B$601,MATCH(S33,Empleadores!$A$2:$A$601,0)),"No encontrado")) | U33: =IF(C33="","",IF(V33="","No",IF(Config!$C$4-V33<=Config!$C$15,"Sí","No"))) -> No
A34: 33 | B34: 010101173G | C34: QUIROGA QUISPE KATHERINE | D34: F | E34: Cusco | F34: 2017-II | G34: 43137 | H34: =IF(G34="","",ROUND((Config!$C$4-G34)/365.25,2)) -> 8.65 | I34: =IF(H34="","",IF(H34<=1,"Tramo 1",IF(H34<=3,"Tramo 2",IF(H34<=5,"Tramo 3","Tramo 4")))) -> Tramo 4 | J34: Titulado | L34: KATHQQ_5@HOTMAIL.COM | M34: 967741192 | O34: Asistencial | P34: =IF(OR(O34="",O34="Sin información"),"",IFERROR(INDEX(Listas!$B$2:$B$9,MATCH(O34,Listas!$A$2:$A$9,0)),"")) -> Sí | Q34: =IF(OR(O34="",O34="Sin información"),"",IFERROR(INDEX(Listas!$C$2:$C$9,MATCH(O34,Listas!$A$2:$A$9,0)),"")) -> Sí | S34: EMP-001 | T34: =IF(S34="","",IFERROR(INDEX(Empleadores!$B$2:$B$601,MATCH(S34,Empleadores!$A$2:$A$601,0)),"No encontrado")) -> Hospital Regional del Cusco | U34: =IF(C34="","",IF(V34="","No",IF(Config!$C$4-V34<=Config!$C$15,"Sí","No"))) -> Sí | V34: 45972 | Y34: Sí | Z34: Marcó 'Otros' en el Encuentro: verificar si es residentado | AB34: I Encuentro de Egresados
A35: 34 | B35: 010101175J | C35: QUISPE ORIHUELA LIZBETH | D35: F | E35: Cusco | F35: 2017-II | G35: 43137 | H35: =IF(G35="","",ROUND((Config!$C$4-G35)/365.25,2)) -> 8.65 | I35: =IF(H35="","",IF(H35<=1,"Tramo 1",IF(H35<=3,"Tramo 2",IF(H35<=5,"Tramo 3","Tramo 4")))) -> Tramo 4 | J35: Titulado | L35: lizonet@hotmail.com | M35: 966741836 | O35: Asistencial | P35: =IF(OR(O35="",O35="Sin información"),"",IFERROR(INDEX(Listas!$B$2:$B$9,MATCH(O35,Listas!$A$2:$A$9,0)),"")) -> Sí | Q35: =IF(OR(O35="",O35="Sin información"),"",IFERROR(INDEX(Listas!$C$2:$C$9,MATCH(O35,Listas!$A$2:$A$9,0)),"")) -> Sí | S35: EMP-022 | T35: =IF(S35="","",IFERROR(INDEX(Empleadores!$B$2:$B$601,MATCH(S35,Empleadores!$A$2:$A$601,0)),"No encontrado")) -> Clínica SOS | U35: =IF(C35="","",IF(V35="","No",IF(Config!$C$4-V35<=Config!$C$15,"Sí","No"))) -> Sí | V35: 45974 | Y35: Sí | AB35: I Encuentro de Egresados
A36: 35 | B36: 010101178I | C36: ROBLES MENDOZA CRISBETH MADISON | D36: F | E36: Cusco | F36: 2017-II | G36: 43137 | H36: =IF(G36="","",ROUND((Config!$C$4-G36)/365.25,2)) -> 8.65 | I36: =IF(H36="","",IF(H36<=1,"Tramo 1",IF(H36<=3,"Tramo 2",IF(H36<=5,"Tramo 3","Tramo 4")))) -> Tramo 4 | J36: Titulado | L36: crisbethmadison@hotmail.com | M36: 955717172 | O36: Sin información | P36: =IF(OR(O36="",O36="Sin información"),"",IFERROR(INDEX(Listas!$B$2:$B$9,MATCH(O36,Listas!$A$2:$A$9,0)),"")) | Q36: =IF(OR(O36="",O36="Sin información"),"",IFERROR(INDEX(Listas!$C$2:$C$9,MATCH(O36,Listas!$A$2:$A$9,0)),"")) | T36: =IF(S36="","",IFERROR(INDEX(Empleadores!$B$2:$B$601,MATCH(S36,Empleadores!$A$2:$A$601,0)),"No encontrado")) | U36: =IF(C36="","",IF(V36="","No",IF(Config!$C$4-V36<=Config!$C$15,"Sí","No"))) -> No
A37: 36 | B37: 010200072D | C37: RODRIGUEZ HUAMAN LUZ MILAGROS | D37: F | E37: Cusco | F37: 2017-II | G37: 43137 | H37: =IF(G37="","",ROUND((Config!$C$4-G37)/365.25,2)) -> 8.65 | I37: =IF(H37="","",IF(H37<=1,"Tramo 1",IF(H37<=3,"Tramo 2",IF(H37<=5,"Tramo 3","Tramo 4")))) -> Tramo 4 | J37: Titulado | L37: xluzx@outlook.es | M37: 987880314 | O37: Sin información | P37: =IF(OR(O37="",O37="Sin información"),"",IFERROR(INDEX(Listas!$B$2:$B$9,MATCH(O37,Listas!$A$2:$A$9,0)),"")) | Q37: =IF(OR(O37="",O37="Sin información"),"",IFERROR(INDEX(Listas!$C$2:$C$9,MATCH(O37,Listas!$A$2:$A$9,0)),"")) | T37: =IF(S37="","",IFERROR(INDEX(Empleadores!$B$2:$B$601,MATCH(S37,Empleadores!$A$2:$A$601,0)),"No encontrado")) | U37: =IF(C37="","",IF(V37="","No",IF(Config!$C$4-V37<=Config!$C$15,"Sí","No"))) -> No
A38: 37 | B38: 011100459C | C38: SOLIS LLAVILLA JANETH MIRIAM | D38: F | E38: Cusco | F38: 2017-II | G38: 43137 | H38: =IF(G38="","",ROUND((Config!$C$4-G38)/365.25,2)) -> 8.65 | I38: =IF(H38="","",IF(H38<=1,"Tramo 1",IF(H38<=3,"Tramo 2",IF(H38<=5,"Tramo 3","Tramo 4")))) -> Tramo 4 | J38: Titulado | L38: janeth_17ms@hotmail.com | M38: 974339700 | O38: Asistencial | P38: =IF(OR(O38="",O38="Sin información"),"",IFERROR(INDEX(Listas!$B$2:$B$9,MATCH(O38,Listas!$A$2:$A$9,0)),"")) -> Sí | Q38: =IF(OR(O38="",O38="Sin información"),"",IFERROR(INDEX(Listas!$C$2:$C$9,MATCH(O38,Listas!$A$2:$A$9,0)),"")) -> Sí | S38: EMP-027 | T38: =IF(S38="","",IFERROR(INDEX(Empleadores!$B$2:$B$601,MATCH(S38,Empleadores!$A$2:$A$601,0)),"No encontrado")) -> Hospital Nacional PNP Luis N. Sáenz | U38: =IF(C38="","",IF(V38="","No",IF(Config!$C$4-V38<=Config!$C$15,"Sí","No"))) -> Sí | V38: 45971 | Y38: Sí | Z38: Marcó 'Otros' en el Encuentro: verificar si es residentado | AB38: I Encuentro de Egresados
A39: 38 | B39: 010101181J | C39: SUTTA VISA MARIBEL | D39: F | E39: Cusco | F39: 2017-II | G39: 43137 | H39: =IF(G39="","",ROUND((Config!$C$4-G39)/365.25,2)) -> 8.65 | I39: =IF(H39="","",IF(H39<=1,"Tramo 1",IF(H39<=3,"Tramo 2",IF(H39<=5,"Tramo 3","Tramo 4")))) -> Tramo 4 | J39: Titulado | L39: maisa3618@hotmail.com | M39: 980998091 | O39: Sin información | P39: =IF(OR(O39="",O39="Sin información"),"",IFERROR(INDEX(Listas!$B$2:$B$9,MATCH(O39,Listas!$A$2:$A$9,0)),"")) | Q39: =IF(OR(O39="",O39="Sin información"),"",IFERROR(INDEX(Listas!$C$2:$C$9,MATCH(O39,Listas!$A$2:$A$9,0)),"")) | T39: =IF(S39="","",IFERROR(INDEX(Empleadores!$B$2:$B$601,MATCH(S39,Empleadores!$A$2:$A$601,0)),"No encontrado")) | U39: =IF(C39="","",IF(V39="","No",IF(Config!$C$4-V39<=Config!$C$15,"Sí","No"))) -> No
A40: 39 | B40: 010101182F | C40: TRUJILLO HANCCO DEYSI IVONNE | D40: F | E40: Cusco | F40: 2017-II | G40: 43137 | H40: =IF(G40="","",ROUND((Config!$C$4-G40)/365.25,2)) -> 8.65 | I40: =IF(H40="","",IF(H40<=1,"Tramo 1",IF(H40<=3,"Tramo 2",IF(H40<=5,"Tramo 3","Tramo 4")))) -> Tramo 4 | J40: Titulado | L40: divonneth@hotmail.com | M40: 958605054 | O40: Asistencial | P40: =IF(OR(O40="",O40="Sin información"),"",IFERROR(INDEX(Listas!$B$2:$B$9,MATCH(O40,Listas!$A$2:$A$9,0)),"")) -> Sí | Q40: =IF(OR(O40="",O40="Sin información"),"",IFERROR(INDEX(Listas!$C$2:$C$9,MATCH(O40,Listas!$A$2:$A$9,0)),"")) -> Sí | S40: EMP-006 | T40: =IF(S40="","",IFERROR(INDEX(Empleadores!$B$2:$B$601,MATCH(S40,Empleadores!$A$2:$A$601,0)),"No encontrado")) -> Hospital Nacional Adolfo Guevara Velasco | U40: =IF(C40="","",IF(V40="","No",IF(Config!$C$4-V40<=Config!$C$15,"Sí","No"))) -> Sí | V40: 45969 | Y40: Sí | AB40: I Encuentro de Egresados
...

Sheet Empleadores
A1: ID empleador | B1: Institución / razón social | C1: RUC | D1: Tipo de institución | E1: Sector | F1: Red / región | G1: Ciudad | H1: Contacto | I1: Cargo del contacto | J1: Correo | K1: Teléfono | L1: Egresados UAC registrados | M1: Encuesta F1-SSEG-02 respondida | N1: Satisfacción del empleador (1–5) | O1: Fecha de encuesta
A2: EMP-001 | B2: Hospital Regional del Cusco | D2: Hospital | E2: MINSA | F2: DIRESA Cusco | G2: Cusco | L2: =IF(A2="","",COUNTIF(Egresados!$S$2:$S$1501,A2)) -> 4
A3: EMP-002 | B3: Clínica Gold Medical | D3: Clínica | E3: Privado | F3: — | G3: Cusco | L3: =IF(A3="","",COUNTIF(Egresados!$S$2:$S$1501,A3)) -> 3
A4: EMP-003 | B4: Hospital de la Solidaridad – Cusco | D4: Hospital | E4: Otro | F4: SISOL | G4: Cusco | L4: =IF(A4="","",COUNTIF(Egresados!$S$2:$S$1501,A4)) -> 3
A5: EMP-004 | B5: Universidad Andina del Cusco – EP Medicina Humana | D5: Universidad | E5: Universidad | F5: — | G5: Cusco | L5: =IF(A5="","",COUNTIF(Egresados!$S$2:$S$1501,A5)) -> 3
A6: EMP-005 | B6: Hospital Antonio Lorena | D6: Hospital | E6: MINSA | F6: DIRESA Cusco | G6: Cusco | L6: =IF(A6="","",COUNTIF(Egresados!$S$2:$S$1501,A6)) -> 2
A7: EMP-006 | B7: Hospital Nacional Adolfo Guevara Velasco | D7: Hospital | E7: EsSalud | F7: Red Asistencial Cusco | G7: Cusco | L7: =IF(A7="","",COUNTIF(Egresados!$S$2:$S$1501,A7)) -> 2
A8: EMP-007 | B8: C.S. Calca | D8: Centro de salud | E8: MINSA | F8: DIRESA Cusco | G8: Calca | L8: =IF(A8="","",COUNTIF(Egresados!$S$2:$S$1501,A8)) -> 1
A9: EMP-008 | B9: C.S. Combapata | D9: Centro de salud | E9: MINSA | F9: DIRESA Cusco | G9: Combapata | L9: =IF(A9="","",COUNTIF(Egresados!$S$2:$S$1501,A9)) -> 1
A10: EMP-009 | B10: C.S. La Quebrada – Yanatile | D10: Centro de salud | E10: MINSA | F10: DIRESA Cusco | G10: Yanatile | L10: =IF(A10="","",COUNTIF(Egresados!$S$2:$S$1501,A10)) -> 1
A11: EMP-010 | B11: C.S. Ollantaytambo | D11: Centro de salud | E11: MINSA | F11: DIRESA Cusco | G11: Ollantaytambo | L11: =IF(A11="","",COUNTIF(Egresados!$S$2:$S$1501,A11)) -> 1
A12: EMP-011 | B12: C.S. Santo Tomás – Chumbivilcas | D12: Centro de salud | E12: MINSA | F12: DIRESA Cusco | G12: Santo Tomás | L12: =IF(A12="","",COUNTIF(Egresados!$S$2:$S$1501,A12)) -> 1
A13: EMP-012 | B13: C.S. Tamburco | D13: Centro de salud | E13: MINSA | F13: DIRESA Apurímac | G13: Abancay | L13: =IF(A13="","",COUNTIF(Egresados!$S$2:$S$1501,A13)) -> 1
... A48: EMP-047 | B48: Sanidad PNP – Quillabamba | D48: Centro de salud | E48: FF.AA. y PNP | F48: Sanidad PNP | G48: Quillabamba | L48: =IF(A48="","",COUNTIF(Egresados!$S$2:$S$1501,A48)) -> 1
L49: =IF(A49="","",COUNTIF(Egresados!$S$2:$S$1501,A49))
L50: =IF(A50="","",COUNTIF(Egresados!$S$2:$S$1501,A50))
L51: =IF(A51="","",COUNTIF(Egresados!$S$2:$S$1501,A51))
L52: =IF(A52="","",COUNTIF(Egresados!$S$2:$S$1501,A52))
L53: =IF(A53="","",COUNTIF(Egresados!$S$2:$S$1501,A53))
L54: =IF(A54="","",COUNTIF(Egresados!$S$2:$S$1501,A54))
L55: =IF(A55="","",COUNTIF(Egresados!$S$2:$S$1501,A55))
L56: =IF(A56="","",COUNTIF(Egresados!$S$2:$S$1501,A56))
L57: =IF(A57="","",COUNTIF(Egresados!$S$2:$S$1501,A57))
L58: =IF(A58="","",COUNTIF(Egresados!$S$2:$S$1501,A58))
L59: =IF(A59="","",COUNTIF(Egresados!$S$2:$S$1501,A59))
L60: =IF(A60="","",COUNTIF(Egresados!$S$2:$S$1501,A60))
... L601: =IF(A601="","",COUNTIF(Egresados!$S$2:$S$1501,A601))

Sheet Actividades
A1: N.° | B1: Fecha | C1: Mes | D1: Actividad | E1: Tipo de actividad | F1: Tramo dirigido | G1: Coordina con | H1: Programada en el Plan | I1: Estado | J1: Participantes (n) | K1: Evidencia | L1: Enlace a evidencia | M1: Observaciones
A2: 1 | B2: 45800 | C2: =IF(B2="","",CHOOSE(MONTH(B2),"Enero","Febrero","Marzo","Abril","Mayo","Junio","Julio","Agosto","Setiembre","Octubre","Noviembre","Diciembre")) -> Mayo | D2: Llamadas de seguimiento a egresados 2022-I | E2: Actualización de BD | F2: Tramo 3 | G2: Servicios Académicos | I2: Ejecutada | J2: 59 | K2: Registro de llamadas (BD 2022-I) | M2: 31 de 59 egresados respondieron; 23 may. al 16 jun. 2025
A3: 2 | B3: 45946 | C3: =IF(B3="","",CHOOSE(MONTH(B3),"Enero","Febrero","Marzo","Abril","Mayo","Junio","Julio","Agosto","Setiembre","Octubre","Noviembre","Diciembre")) -> Octubre | D3: Encuesta a egresados 2024-2025 (situación laboral y SERUMS) | E3: Aplicación de encuesta | F3: Tramo 2 | G3: DIRSEU | I3: Ejecutada | J3: 34 | K3: Respuestas de formulario (Google Forms) | M3: 36 respuestas; 16 al 26 oct. 2025
A4: 3 | B4: 45960 | C4: =IF(B4="","",CHOOSE(MONTH(B4),"Enero","Febrero","Marzo","Abril","Mayo","Junio","Julio","Agosto","Setiembre","Octubre","Noviembre","Diciembre")) -> Octubre | D4: I Encuentro de Egresados de Medicina Humana | E4: Evento académico | F4: Todos | G4: Asociación de Egresados | I4: Ejecutada | J4: 76 | K4: Registro de asistencia (formulario) | M4: 92 registros; asistentes identificados en la relación oficial
A5: 4 | B5: 45974 | C5: =IF(B5="","",CHOOSE(MONTH(B5),"Enero","Febrero","Marzo","Abril","Mayo","Junio","Julio","Agosto","Setiembre","Octubre","Noviembre","Diciembre")) -> Noviembre | D5: Encuesta primera de egreso (satisfacción con la formación) | E5: Aplicación de encuesta | F5: Tramo 2 | G5: DIRSEU | I5: Ejecutada | J5: 13 | K5: Respuestas de formulario | M5: 13 respuestas; 13 nov. al 9 dic. 2025
A6: 5 | B6: 46244 | C6: =IF(B6="","",CHOOSE(MONTH(B6),"Enero","Febrero","Marzo","Abril","Mayo","Junio","Julio","Agosto","Setiembre","Octubre","Noviembre","Diciembre")) -> Agosto | D6: Encuesta a egresados que son docentes de la EPMH | E6: Aplicación de encuesta | F6: Todos | G6: Departamento Académico | I6: Ejecutada | J6: 11 | K6: Respuestas de formulario | M6: 11 docentes egresados; 8 egresaron antes de 2017-2 (ver Por conciliar)
A7: 6 | B7: 46296 | C7: =IF(B7="","",CHOOSE(MONTH(B7),"Enero","Febrero","Marzo","Abril","Mayo","Junio","Julio","Agosto","Setiembre","Octubre","Noviembre","Diciembre")) -> Octubre | D7: Cruce con resultados finales SERUMS 2026-II (MINSA) | E7: Actualización de BD | F7: Todos | G7: DIRSEU | I7: Ejecutada | J7: 158 | K7: Egresados_UAC_SERUMS_2026-II.xlsx | M7: 153 evaluados, 4 no se presentaron, 1 ficha inválida
